Not using distributed mode
Creating vqa datasets
Creating model
reshape position embedding from 256 to 576
load checkpoint from /home/admin1/5703-upload/5703/Transformer_VQA_no/ALBEF.pth and ALBEF.fusion ##new , fuse the img and pseduo prompt after inversion
Traceback (most recent call last):
  File "/home/admin1/5703-upload/5703/Transformer_VQA_no/run_vqa2.py", line 368, in <module>
    main(args, config)
  File "/home/admin1/5703-upload/5703/Transformer_VQA_no/run_vqa2.py", line 298, in main
    train_stats = train(model, train_loader, optimizer, tokenizer, epoch, warmup_steps, device, lr_scheduler, config)
  File "/home/admin1/5703-upload/5703/Transformer_VQA_no/run_vqa2.py", line 77, in train
    for i,(image, question, answer, weights, n) in enumerate(metric_logger.log_every(data_loader, print_freq, header)):
  File "/home/admin1/5703-upload/5703/Transformer_VQA_no/utils.py", line 137, in log_every
    for obj in iterable:
  File "/home/admin1/anconda3/envs/pytorch2.0/lib/python3.9/site-packages/torch/utils/data/dataloader.py", line 633, in __next__
    data = self._next_data()
  File "/home/admin1/anconda3/envs/pytorch2.0/lib/python3.9/site-packages/torch/utils/data/dataloader.py", line 1345, in _next_data
    return self._process_data(data)
  File "/home/admin1/anconda3/envs/pytorch2.0/lib/python3.9/site-packages/torch/utils/data/dataloader.py", line 1371, in _process_data
    data.reraise()
  File "/home/admin1/anconda3/envs/pytorch2.0/lib/python3.9/site-packages/torch/_utils.py", line 644, in reraise
    raise exception
FileNotFoundError: Caught FileNotFoundError in DataLoader worker process 0.
Original Traceback (most recent call last):
  File "/home/admin1/anconda3/envs/pytorch2.0/lib/python3.9/site-packages/torch/utils/data/_utils/worker.py", line 308, in _worker_loop
    data = fetcher.fetch(index)
  File "/home/admin1/anconda3/envs/pytorch2.0/lib/python3.9/site-packages/torch/utils/data/_utils/fetch.py", line 51, in fetch
    data = [self.dataset[idx] for idx in possibly_batched_index]
  File "/home/admin1/anconda3/envs/pytorch2.0/lib/python3.9/site-packages/torch/utils/data/_utils/fetch.py", line 51, in <listcomp>
    data = [self.dataset[idx] for idx in possibly_batched_index]
  File "/home/admin1/5703-upload/5703/Transformer_VQA_no/dataset/vqa_dataset.py", line 36, in __getitem__
    image = Image.open(image_path).convert('RGB')
  File "/home/admin1/anconda3/envs/pytorch2.0/lib/python3.9/site-packages/PIL/Image.py", line 3277, in open
    fp = builtins.open(filename, "rb")
FileNotFoundError: [Errno 2] No such file or directory: '/home/admin1/5703-upload/5703/Transformer_VQA_COCO/train2014/train2014/COCO_train2014_000000528937.jpg'