2024-05-25 16:45:37,165 INFO    MainThread:6225 [wandb_setup.py:_flush():76] Current SDK version is 0.16.5
2024-05-25 16:45:37,165 INFO    MainThread:6225 [wandb_setup.py:_flush():76] Configure stats pid to 6225
2024-05-25 16:45:37,165 INFO    MainThread:6225 [wandb_setup.py:_flush():76] Loading settings from /home/admin1/.config/wandb/settings
2024-05-25 16:45:37,165 INFO    MainThread:6225 [wandb_setup.py:_flush():76] Loading settings from /home/admin1/5703-upload/5703/Transformer_VQA_no/wandb/settings
2024-05-25 16:45:37,165 INFO    MainThread:6225 [wandb_setup.py:_flush():76] Loading settings from environment variables: {}
2024-05-25 16:45:37,165 INFO    MainThread:6225 [wandb_setup.py:_flush():76] Applying setup settings: {'_disable_service': False}
2024-05-25 16:45:37,165 INFO    MainThread:6225 [wandb_setup.py:_flush():76] Inferring run settings from compute environment: {'program_relpath': 'run.py', 'program_abspath': '/home/admin1/5703-upload/5703/Transformer_VQA_no/run.py', 'program': '/home/admin1/5703-upload/5703/Transformer_VQA_no/run.py'}
2024-05-25 16:45:37,165 INFO    MainThread:6225 [wandb_setup.py:_flush():76] Applying login settings: {}
2024-05-25 16:45:37,165 INFO    MainThread:6225 [wandb_init.py:_log_setup():527] Logging user logs to /home/admin1/5703-upload/5703/Transformer_VQA_no/wandb/run-20240525_164537-hjwyjqd6/logs/debug.log
2024-05-25 16:45:37,165 INFO    MainThread:6225 [wandb_init.py:_log_setup():528] Logging internal logs to /home/admin1/5703-upload/5703/Transformer_VQA_no/wandb/run-20240525_164537-hjwyjqd6/logs/debug-internal.log
2024-05-25 16:45:37,166 INFO    MainThread:6225 [wandb_init.py:init():567] calling init triggers
2024-05-25 16:45:37,166 INFO    MainThread:6225 [wandb_init.py:init():574] wandb.init called with sweep_config: {}
config: {'config': 'config3'}
2024-05-25 16:45:37,166 INFO    MainThread:6225 [wandb_init.py:init():617] starting backend
2024-05-25 16:45:37,166 INFO    MainThread:6225 [wandb_init.py:init():621] setting up manager
2024-05-25 16:45:37,168 INFO    MainThread:6225 [backend.py:_multiprocessing_setup():105] multiprocessing start_methods=fork,spawn,forkserver, using: spawn
2024-05-25 16:45:37,170 INFO    MainThread:6225 [wandb_init.py:init():629] backend started and connected
2024-05-25 16:45:37,175 INFO    MainThread:6225 [wandb_init.py:init():721] updated telemetry
2024-05-25 16:45:37,175 INFO    MainThread:6225 [wandb_init.py:init():754] communicating run to backend with 90.0 second timeout
2024-05-25 16:46:05,920 INFO    Thread-1  :6225 [retry.py:__call__():172] Retry attempt failed:
Traceback (most recent call last):
  File "/home/admin1/anconda3/envs/pytorch2.0/lib/python3.9/site-packages/urllib3/connection.py", line 198, in _new_conn
    sock = connection.create_connection(
  File "/home/admin1/anconda3/envs/pytorch2.0/lib/python3.9/site-packages/urllib3/util/connection.py", line 60, in create_connection
    for res in socket.getaddrinfo(host, port, family, socket.SOCK_STREAM):
  File "/home/admin1/anconda3/envs/pytorch2.0/lib/python3.9/socket.py", line 954, in getaddrinfo
    for res in _socket.getaddrinfo(host, port, family, type, proto, flags):
socket.gaierror: [Errno -3] Temporary failure in name resolution

The above exception was the direct cause of the following exception:

Traceback (most recent call last):
  File "/home/admin1/anconda3/envs/pytorch2.0/lib/python3.9/site-packages/urllib3/connectionpool.py", line 793, in urlopen
    response = self._make_request(
  File "/home/admin1/anconda3/envs/pytorch2.0/lib/python3.9/site-packages/urllib3/connectionpool.py", line 491, in _make_request
    raise new_e
  File "/home/admin1/anconda3/envs/pytorch2.0/lib/python3.9/site-packages/urllib3/connectionpool.py", line 467, in _make_request
    self._validate_conn(conn)
  File "/home/admin1/anconda3/envs/pytorch2.0/lib/python3.9/site-packages/urllib3/connectionpool.py", line 1099, in _validate_conn
    conn.connect()
  File "/home/admin1/anconda3/envs/pytorch2.0/lib/python3.9/site-packages/urllib3/connection.py", line 616, in connect
    self.sock = sock = self._new_conn()
  File "/home/admin1/anconda3/envs/pytorch2.0/lib/python3.9/site-packages/urllib3/connection.py", line 205, in _new_conn
    raise NameResolutionError(self.host, self, e) from e
urllib3.exceptions.NameResolutionError: <urllib3.connection.HTTPSConnection object at 0x7f0f749c04c0>: Failed to resolve 'api.wandb.ai' ([Errno -3] Temporary failure in name resolution)

The above exception was the direct cause of the following exception:

Traceback (most recent call last):
  File "/home/admin1/anconda3/envs/pytorch2.0/lib/python3.9/site-packages/requests/adapters.py", line 486, in send
    resp = conn.urlopen(
  File "/home/admin1/anconda3/envs/pytorch2.0/lib/python3.9/site-packages/urllib3/connectionpool.py", line 847, in urlopen
    retries = retries.increment(
  File "/home/admin1/anconda3/envs/pytorch2.0/lib/python3.9/site-packages/urllib3/util/retry.py", line 515, in increment
    raise MaxRetryError(_pool, url, reason) from reason  # type: ignore[arg-type]
urllib3.exceptions.MaxRetryError: HTTPSConnectionPool(host='api.wandb.ai', port=443): Max retries exceeded with url: /graphql (Caused by NameResolutionError("<urllib3.connection.HTTPSConnection object at 0x7f0f749c04c0>: Failed to resolve 'api.wandb.ai' ([Errno -3] Temporary failure in name resolution)"))

During handling of the above exception, another exception occurred:

Traceback (most recent call last):
  File "/home/admin1/anconda3/envs/pytorch2.0/lib/python3.9/site-packages/wandb/sdk/lib/retry.py", line 131, in __call__
    result = self._call_fn(*args, **kwargs)
  File "/home/admin1/anconda3/envs/pytorch2.0/lib/python3.9/site-packages/wandb/sdk/internal/internal_api.py", line 369, in execute
    return self.client.execute(*args, **kwargs)  # type: ignore
  File "/home/admin1/anconda3/envs/pytorch2.0/lib/python3.9/site-packages/wandb/vendor/gql-0.2.0/wandb_gql/client.py", line 52, in execute
    result = self._get_result(document, *args, **kwargs)
  File "/home/admin1/anconda3/envs/pytorch2.0/lib/python3.9/site-packages/wandb/vendor/gql-0.2.0/wandb_gql/client.py", line 60, in _get_result
    return self.transport.execute(document, *args, **kwargs)
  File "/home/admin1/anconda3/envs/pytorch2.0/lib/python3.9/site-packages/wandb/sdk/lib/gql_request.py", line 58, in execute
    request = self.session.post(self.url, **post_args)
  File "/home/admin1/anconda3/envs/pytorch2.0/lib/python3.9/site-packages/requests/sessions.py", line 637, in post
    return self.request("POST", url, data=data, json=json, **kwargs)
  File "/home/admin1/anconda3/envs/pytorch2.0/lib/python3.9/site-packages/requests/sessions.py", line 589, in request
    resp = self.send(prep, **send_kwargs)
  File "/home/admin1/anconda3/envs/pytorch2.0/lib/python3.9/site-packages/requests/sessions.py", line 703, in send
    r = adapter.send(request, **kwargs)
  File "/home/admin1/anconda3/envs/pytorch2.0/lib/python3.9/site-packages/requests/adapters.py", line 519, in send
    raise ConnectionError(e, request=request)
requests.exceptions.ConnectionError: HTTPSConnectionPool(host='api.wandb.ai', port=443): Max retries exceeded with url: /graphql (Caused by NameResolutionError("<urllib3.connection.HTTPSConnection object at 0x7f0f749c04c0>: Failed to resolve 'api.wandb.ai' ([Errno -3] Temporary failure in name resolution)"))
2024-05-25 16:46:39,792 INFO    MainThread:6225 [wandb_run.py:_on_init():2344] communicating current version
2024-05-25 16:46:42,947 INFO    MainThread:6225 [wandb_run.py:_on_init():2353] got version response 
2024-05-25 16:46:42,947 INFO    MainThread:6225 [wandb_init.py:init():805] starting run threads in backend
2024-05-25 16:46:45,666 INFO    MainThread:6225 [wandb_run.py:_console_start():2323] atexit reg
2024-05-25 16:46:45,666 INFO    MainThread:6225 [wandb_run.py:_redirect():2178] redirect: wrap_raw
2024-05-25 16:46:45,666 INFO    MainThread:6225 [wandb_run.py:_redirect():2243] Wrapping output streams.
2024-05-25 16:46:45,666 INFO    MainThread:6225 [wandb_run.py:_redirect():2268] Redirects installed.
2024-05-25 16:46:45,667 INFO    MainThread:6225 [wandb_init.py:init():848] run started, returning control to user process
2024-05-25 17:57:28,697 WARNING MsgRouterThr:6225 [router.py:message_loop():77] message_loop has been closed
